[2022-09-06 17:33:12,526] {taskinstance.py:1179} INFO - Dependencies all met for <TaskInstance: data_cleaning_dag.data_cleaning manual__2022-09-06T17:33:09.642915+00:00 [queued]>
[2022-09-06 17:33:12,577] {taskinstance.py:1179} INFO - Dependencies all met for <TaskInstance: data_cleaning_dag.data_cleaning manual__2022-09-06T17:33:09.642915+00:00 [queued]>
[2022-09-06 17:33:12,587] {taskinstance.py:1376} INFO - 
--------------------------------------------------------------------------------
[2022-09-06 17:33:12,596] {taskinstance.py:1377} INFO - Starting attempt 1 of 1
[2022-09-06 17:33:12,599] {taskinstance.py:1378} INFO - 
--------------------------------------------------------------------------------
[2022-09-06 17:33:12,664] {taskinstance.py:1397} INFO - Executing <Task(PythonOperator): data_cleaning> on 2022-09-06 17:33:09.642915+00:00
[2022-09-06 17:33:12,690] {standard_task_runner.py:52} INFO - Started process 569 to run task
[2022-09-06 17:33:12,720] {standard_task_runner.py:79} INFO - Running: ['***', 'tasks', 'run', 'data_cleaning_dag', 'data_cleaning', 'manual__2022-09-06T17:33:09.642915+00:00', '--job-id', '4', '--raw', '--subdir', 'DAGS_FOLDER/data_cleaning_dag/data_cleaning.py', '--cfg-path', '/tmp/tmpqr0z44bu', '--error-file', '/tmp/tmp5fo5tfc9']
[2022-09-06 17:33:12,727] {standard_task_runner.py:80} INFO - Job 4: Subtask data_cleaning
[2022-09-06 17:33:12,994] {task_command.py:371} INFO - Running <TaskInstance: data_cleaning_dag.data_cleaning manual__2022-09-06T17:33:09.642915+00:00 [running]> on host 9214b146046f
[2022-09-06 17:33:13,219] {taskinstance.py:1591} INFO - Exporting the following env vars:
AIRFLOW_CTX_DAG_OWNER=***
AIRFLOW_CTX_DAG_ID=data_cleaning_dag
AIRFLOW_CTX_TASK_ID=data_cleaning
AIRFLOW_CTX_EXECUTION_DATE=2022-09-06T17:33:09.642915+00:00
AIRFLOW_CTX_TRY_NUMBER=1
AIRFLOW_CTX_DAG_RUN_ID=manual__2022-09-06T17:33:09.642915+00:00
[2022-09-06 17:33:13,226] {taskinstance.py:1909} ERROR - Task failed with exception
Traceback (most recent call last):
  File "/home/airflow/.local/lib/python3.7/site-packages/airflow/operators/python.py", line 171, in execute
    return_value = self.execute_callable()
  File "/home/airflow/.local/lib/python3.7/site-packages/airflow/operators/python.py", line 189, in execute_callable
    return self.python_callable(*self.op_args, **self.op_kwargs)
  File "/opt/airflow/dags/data_cleaning_dag/data_cleaning.py", line 13, in data_cleaning
    hotel_data = pd.read_csv("raw_data/hotel_bookings.csv") # Importing raw data
  File "/home/airflow/.local/lib/python3.7/site-packages/pandas/util/_decorators.py", line 311, in wrapper
    return func(*args, **kwargs)
  File "/home/airflow/.local/lib/python3.7/site-packages/pandas/io/parsers/readers.py", line 586, in read_csv
    return _read(filepath_or_buffer, kwds)
  File "/home/airflow/.local/lib/python3.7/site-packages/pandas/io/parsers/readers.py", line 482, in _read
    parser = TextFileReader(filepath_or_buffer, **kwds)
  File "/home/airflow/.local/lib/python3.7/site-packages/pandas/io/parsers/readers.py", line 811, in __init__
    self._engine = self._make_engine(self.engine)
  File "/home/airflow/.local/lib/python3.7/site-packages/pandas/io/parsers/readers.py", line 1040, in _make_engine
    return mapping[engine](self.f, **self.options)  # type: ignore[call-arg]
  File "/home/airflow/.local/lib/python3.7/site-packages/pandas/io/parsers/c_parser_wrapper.py", line 51, in __init__
    self._open_handles(src, kwds)
  File "/home/airflow/.local/lib/python3.7/site-packages/pandas/io/parsers/base_parser.py", line 229, in _open_handles
    errors=kwds.get("encoding_errors", "strict"),
  File "/home/airflow/.local/lib/python3.7/site-packages/pandas/io/common.py", line 707, in get_handle
    newline="",
FileNotFoundError: [Errno 2] No such file or directory: 'raw_data/hotel_bookings.csv'
[2022-09-06 17:33:13,251] {taskinstance.py:1420} INFO - Marking task as FAILED. dag_id=data_cleaning_dag, task_id=data_cleaning, execution_date=20220906T173309, start_date=20220906T173312, end_date=20220906T173313
[2022-09-06 17:33:13,310] {standard_task_runner.py:97} ERROR - Failed to execute job 4 for task data_cleaning ([Errno 2] No such file or directory: 'raw_data/hotel_bookings.csv'; 569)
[2022-09-06 17:33:13,343] {local_task_job.py:156} INFO - Task exited with return code 1
[2022-09-06 17:33:13,451] {local_task_job.py:273} INFO - 0 downstream tasks scheduled from follow-on schedule check
