[2022-09-06 17:37:09,004] {taskinstance.py:1179} INFO - Dependencies all met for <TaskInstance: data_cleaning_dag.data_cleaning manual__2022-09-06T17:37:05.354629+00:00 [queued]>
[2022-09-06 17:37:09,029] {taskinstance.py:1179} INFO - Dependencies all met for <TaskInstance: data_cleaning_dag.data_cleaning manual__2022-09-06T17:37:05.354629+00:00 [queued]>
[2022-09-06 17:37:09,031] {taskinstance.py:1376} INFO - 
--------------------------------------------------------------------------------
[2022-09-06 17:37:09,033] {taskinstance.py:1377} INFO - Starting attempt 1 of 1
[2022-09-06 17:37:09,034] {taskinstance.py:1378} INFO - 
--------------------------------------------------------------------------------
[2022-09-06 17:37:09,084] {taskinstance.py:1397} INFO - Executing <Task(PythonOperator): data_cleaning> on 2022-09-06 17:37:05.354629+00:00
[2022-09-06 17:37:09,108] {standard_task_runner.py:52} INFO - Started process 755 to run task
[2022-09-06 17:37:09,127] {standard_task_runner.py:79} INFO - Running: ['***', 'tasks', 'run', 'data_cleaning_dag', 'data_cleaning', 'manual__2022-09-06T17:37:05.354629+00:00', '--job-id', '8', '--raw', '--subdir', 'DAGS_FOLDER/data_cleaning_dag/.ipynb_checkpoints/data_cleaning-checkpoint.py', '--cfg-path', '/tmp/tmpgc6fznch', '--error-file', '/tmp/tmp0ip4gh67']
[2022-09-06 17:37:09,133] {standard_task_runner.py:80} INFO - Job 8: Subtask data_cleaning
[2022-09-06 17:37:09,296] {task_command.py:371} INFO - Running <TaskInstance: data_cleaning_dag.data_cleaning manual__2022-09-06T17:37:05.354629+00:00 [running]> on host 9214b146046f
[2022-09-06 17:37:09,458] {taskinstance.py:1591} INFO - Exporting the following env vars:
AIRFLOW_CTX_DAG_OWNER=***
AIRFLOW_CTX_DAG_ID=data_cleaning_dag
AIRFLOW_CTX_TASK_ID=data_cleaning
AIRFLOW_CTX_EXECUTION_DATE=2022-09-06T17:37:05.354629+00:00
AIRFLOW_CTX_TRY_NUMBER=1
AIRFLOW_CTX_DAG_RUN_ID=manual__2022-09-06T17:37:05.354629+00:00
[2022-09-06 17:37:09,468] {taskinstance.py:1909} ERROR - Task failed with exception
Traceback (most recent call last):
  File "/home/airflow/.local/lib/python3.7/site-packages/airflow/operators/python.py", line 171, in execute
    return_value = self.execute_callable()
  File "/home/airflow/.local/lib/python3.7/site-packages/airflow/operators/python.py", line 189, in execute_callable
    return self.python_callable(*self.op_args, **self.op_kwargs)
  File "/opt/airflow/dags/data_cleaning_dag/.ipynb_checkpoints/data_cleaning-checkpoint.py", line 13, in data_cleaning
    hotel_data = pd.read_csv("raw_data/hotel_bookings.csv") # Importing raw data
  File "/home/airflow/.local/lib/python3.7/site-packages/pandas/util/_decorators.py", line 311, in wrapper
    return func(*args, **kwargs)
  File "/home/airflow/.local/lib/python3.7/site-packages/pandas/io/parsers/readers.py", line 586, in read_csv
    return _read(filepath_or_buffer, kwds)
  File "/home/airflow/.local/lib/python3.7/site-packages/pandas/io/parsers/readers.py", line 482, in _read
    parser = TextFileReader(filepath_or_buffer, **kwds)
  File "/home/airflow/.local/lib/python3.7/site-packages/pandas/io/parsers/readers.py", line 811, in __init__
    self._engine = self._make_engine(self.engine)
  File "/home/airflow/.local/lib/python3.7/site-packages/pandas/io/parsers/readers.py", line 1040, in _make_engine
    return mapping[engine](self.f, **self.options)  # type: ignore[call-arg]
  File "/home/airflow/.local/lib/python3.7/site-packages/pandas/io/parsers/c_parser_wrapper.py", line 51, in __init__
    self._open_handles(src, kwds)
  File "/home/airflow/.local/lib/python3.7/site-packages/pandas/io/parsers/base_parser.py", line 229, in _open_handles
    errors=kwds.get("encoding_errors", "strict"),
  File "/home/airflow/.local/lib/python3.7/site-packages/pandas/io/common.py", line 707, in get_handle
    newline="",
FileNotFoundError: [Errno 2] No such file or directory: 'raw_data/hotel_bookings.csv'
[2022-09-06 17:37:09,495] {taskinstance.py:1420} INFO - Marking task as FAILED. dag_id=data_cleaning_dag, task_id=data_cleaning, execution_date=20220906T173705, start_date=20220906T173709, end_date=20220906T173709
[2022-09-06 17:37:09,527] {standard_task_runner.py:97} ERROR - Failed to execute job 8 for task data_cleaning ([Errno 2] No such file or directory: 'raw_data/hotel_bookings.csv'; 755)
[2022-09-06 17:37:09,584] {local_task_job.py:156} INFO - Task exited with return code 1
[2022-09-06 17:37:09,655] {local_task_job.py:273} INFO - 0 downstream tasks scheduled from follow-on schedule check
